Workbook

Sheet Assessment Info
A1: Assessment Information
A2: Fictional example. All evidence, scores, and findings are illustrative.
A4: Assessment title | B4: Cybersecurity Risk Register with NIST CSF 2.0 Gap Analysis
A5: Organization | B5: BrightPath Dental, a fictional US-based dental clinic with 40 staff at a single location. Assumed to be subject to HIPAA and US state breach-notification laws.
A6: Prepared by | B6: Sakar Singh Khadka
A7: Assessment date | B7: 46287
A8: Version | B8: 1.0
A9: Scope: in | B9: Patient records cloud application, 30 Windows laptops, office Wi-Fi and router, cloud backup, key vendors, and the staff and IT contractor who use them.
A10: Scope: out | B10: Staff personal devices, dental imaging equipment, and building infrastructure managed by the landlord.
A11: Framework coverage | B11: NIST Cybersecurity Framework 2.0. This workbook assesses 26 selected outcomes (subcategories) across all six functions, not the entire framework. The outcomes were chosen to fit a small clinic.
A12: Maturity scoring | B12: Current and Target scores use a custom 0-4 scale (see 'Scales'). NIST CSF is outcome-based and does not prescribe maturity levels or scores. Target scores reflect what a small clinic could reasonably achieve.
A13: Gap and priority | B13: Gap = Target - Current (minimum 0). Priority score = Gap x Impact (Impact on a 1-5 scale).
A14: Risk rating | B14: Risk score = Likelihood x Impact (1-5 each). High is 12 or more, Medium is 6 to 11, Low is below 6. Residual risk uses the same scales and is the expected score once the planned action is complete.
A15: Evidence sources (fictional) | B15: Interviews with the owner and the IT contractor; document requests; review of records-system and router settings; sample of 5 of 30 laptops; backup job logs; vendor documentation; sample of 5 recent leavers.
A16: Assumptions | B16: 1) The clinic is US-based and HIPAA applies. 2) All evidence is fictional and was written for this exercise. 3) Scores are one assessor's judgment. 4) No technical testing or scanning was performed.
A17: Limitations | B17: Qualitative scoring by one assessor; a selected subset of outcomes; requirement wording is shortened from the official framework.
A18: Source | B18: NIST Cybersecurity Framework 2.0 (https://www.nist.gov/cyberframework)

Sheet Risk Register
A1: Cybersecurity Risk Register: BrightPath Dental (fictional US-based clinic)
A4: Risk ID | B4: Risk description | C4: CSF ID | D4: Likelihood (1-5) | E4: Impact (1-5) | F4: Score | G4: Level | H4: CSF gap (target - current) | I4: Treatment | J4: Planned action | K4: Residual likelihood (target) | L4: Residual impact (target) | M4: Residual score | N4: Residual level | O4: Owner (role) | P4: Due date | Q4: Status
A5: R-01 | B5: Unauthorized access to patient records through a shared login with no MFA | C5: PR.AA-03 | D5: 4 | E5: 5 | F5: =IF(OR(D5="",E5=""),"",D5*E5) -> 20 | G5: =IF(F5="","",IF(F5>=Scales!$B$21,"High",IF(F5>=Scales!$B$22,"Medium","Low"))) -> High | H5: =IF(C5="","",IFERROR(INDEX('Gap Assessment'!$I$5:$I$100,MATCH(C5,'Gap Assessment'!$A$5:$A$100,0)),"Not found")) -> 2 | I5: Mitigate | J5: Create individual accounts and turn on MFA | K5: 1 | L5: 5 | M5: =IF(OR(K5="",L5=""),"",K5*L5) -> 5 | N5: =IF(M5="","",IF(M5>=Scales!$B$21,"High",IF(M5>=Scales!$B$22,"Medium","Low"))) -> Low | O5: IT contractor | P5: 46356 | Q5: Open
A6: R-02 | B6: Phishing email leads to stolen staff passwords | C6: PR.AT-01 | D6: 4 | E6: 4 | F6: =IF(OR(D6="",E6=""),"",D6*E6) -> 16 | G6: =IF(F6="","",IF(F6>=Scales!$B$21,"High",IF(F6>=Scales!$B$22,"Medium","Low"))) -> High | H6: =IF(C6="","",IFERROR(INDEX('Gap Assessment'!$I$5:$I$100,MATCH(C6,'Gap Assessment'!$A$5:$A$100,0)),"Not found")) -> 2 | I6: Mitigate | J6: Run awareness training and set up a way to report suspicious emails | K6: 2 | L6: 4 | M6: =IF(OR(K6="",L6=""),"",K6*L6) -> 8 | N6: =IF(M6="","",IF(M6>=Scales!$B$21,"High",IF(M6>=Scales!$B$22,"Medium","Low"))) -> Medium | O6: Practice manager | P6: 46418 | Q6: Open
A7: R-03 | B7: Ransomware locks patient systems and backups cannot be restored | C7: PR.DS-11 | D7: 3 | E7: 5 | F7: =IF(OR(D7="",E7=""),"",D7*E7) -> 15 | G7: =IF(F7="","",IF(F7>=Scales!$B$21,"High",IF(F7>=Scales!$B$22,"Medium","Low"))) -> High | H7: =IF(C7="","",IFERROR(INDEX('Gap Assessment'!$I$5:$I$100,MATCH(C7,'Gap Assessment'!$A$5:$A$100,0)),"Not found")) -> 1 | I7: Mitigate | J7: Test restores every quarter and keep an offline backup copy | K7: 1 | L7: 5 | M7: =IF(OR(K7="",L7=""),"",K7*L7) -> 5 | N7: =IF(M7="","",IF(M7>=Scales!$B$21,"High",IF(M7>=Scales!$B$22,"Medium","Low"))) -> Low | O7: IT contractor | P7: 46341 | Q7: Open
A8: R-04 | B8: No incident response plan, so response is slow and breach notice is late | C8: RS.MA-01 | D8: 3 | E8: 5 | F8: =IF(OR(D8="",E8=""),"",D8*E8) -> 15 | G8: =IF(F8="","",IF(F8>=Scales!$B$21,"High",IF(F8>=Scales!$B$22,"Medium","Low"))) -> High | H8: =IF(C8="","",IFERROR(INDEX('Gap Assessment'!$I$5:$I$100,MATCH(C8,'Gap Assessment'!$A$5:$A$100,0)),"Not found")) -> 3 | I8: Mitigate | J8: Write, approve, and practice an incident response plan | K8: 1 | L8: 5 | M8: =IF(OR(K8="",L8=""),"",K8*L8) -> 5 | N8: =IF(M8="","",IF(M8>=Scales!$B$21,"High",IF(M8>=Scales!$B$22,"Medium","Low"))) -> Low | O8: Security lead | P8: 46371 | Q8: Open
A9: R-05 | B9: Lost or stolen laptop that is not encrypted exposes patient data | C9: PR.DS-01 | D9: 3 | E9: 4 | F9: =IF(OR(D9="",E9=""),"",D9*E9) -> 12 | G9: =IF(F9="","",IF(F9>=Scales!$B$21,"High",IF(F9>=Scales!$B$22,"Medium","Low"))) -> High | H9: =IF(C9="","",IFERROR(INDEX('Gap Assessment'!$I$5:$I$100,MATCH(C9,'Gap Assessment'!$A$5:$A$100,0)),"Not found")) -> 1 | I9: Mitigate | J9: Turn on full-disk encryption on all laptops | K9: 1 | L9: 4 | M9: =IF(OR(K9="",L9=""),"",K9*L9) -> 4 | N9: =IF(M9="","",IF(M9>=Scales!$B$21,"High",IF(M9>=Scales!$B$22,"Medium","Low"))) -> Low | O9: IT contractor | P9: 46418 | Q9: Open
A10: R-06 | B10: Former staff keep access to systems after leaving | C10: PR.AA-01 | D10: 3 | E10: 4 | F10: =IF(OR(D10="",E10=""),"",D10*E10) -> 12 | G10: =IF(F10="","",IF(F10>=Scales!$B$21,"High",IF(F10>=Scales!$B$22,"Medium","Low"))) -> High | H10: =IF(C10="","",IFERROR(INDEX('Gap Assessment'!$I$5:$I$100,MATCH(C10,'Gap Assessment'!$A$5:$A$100,0)),"Not found")) -> 2 | I10: Mitigate | J10: Use an offboarding checklist and review accounts monthly | K10: 1 | L10: 4 | M10: =IF(OR(K10="",L10=""),"",K10*L10) -> 4 | N10: =IF(M10="","",IF(M10>=Scales!$B$21,"High",IF(M10>=Scales!$B$22,"Medium","Low"))) -> Low | O10: Practice manager | P10: 46356 | Q10: Open
A11: R-07 | B11: Laptops running unsupported Windows 10 are exploited | C11: PR.PS-02 | D11: 3 | E11: 4 | F11: =IF(OR(D11="",E11=""),"",D11*E11) -> 12 | G11: =IF(F11="","",IF(F11>=Scales!$B$21,"High",IF(F11>=Scales!$B$22,"Medium","Low"))) -> High | H11: =IF(C11="","",IFERROR(INDEX('Gap Assessment'!$I$5:$I$100,MATCH(C11,'Gap Assessment'!$A$5:$A$100,0)),"Not found")) -> 2 | I11: Mitigate | J11: Upgrade or replace unsupported laptops | K11: 1 | L11: 4 | M11: =IF(OR(K11="",L11=""),"",K11*L11) -> 4 | N11: =IF(M11="","",IF(M11>=Scales!$B$21,"High",IF(M11>=Scales!$B$22,"Medium","Low"))) -> Low | O11: IT contractor | P11: 46418 | Q11: Open
A12: R-08 | B12: Data breach at the cloud records vendor | C12: GV.SC-01 | D12: 2 | E12: 5 | F12: =IF(OR(D12="",E12=""),"",D12*E12) -> 10 | G12: =IF(F12="","",IF(F12>=Scales!$B$21,"High",IF(F12>=Scales!$B$22,"Medium","Low"))) -> Medium | H12: =IF(C12="","",IFERROR(INDEX('Gap Assessment'!$I$5:$I$100,MATCH(C12,'Gap Assessment'!$A$5:$A$100,0)),"Not found")) -> 2 | I12: Transfer | J12: Send a security questionnaire, check contract terms, and review cyber insurance | K12: 2 | L12: 3 | M12: =IF(OR(K12="",L12=""),"",K12*L12) -> 6 | N12: =IF(M12="","",IF(M12>=Scales!$B$21,"High",IF(M12>=Scales!$B$22,"Medium","Low"))) -> Medium | O12: Practice owner | P12: 46477 | Q12: Open
A13: R-09 | B13: Intrusion goes unnoticed because nothing is monitored | C13: DE.CM-09 | D13: 3 | E13: 3 | F13: =IF(OR(D13="",E13=""),"",D13*E13) -> 9 | G13: =IF(F13="","",IF(F13>=Scales!$B$21,"High",IF(F13>=Scales!$B$22,"Medium","Low"))) -> Medium | H13: =IF(C13="","",IFERROR(INDEX('Gap Assessment'!$I$5:$I$100,MATCH(C13,'Gap Assessment'!$A$5:$A$100,0)),"Not found")) -> 2 | I13: Mitigate | J13: Deploy endpoint protection with alerts and review logs weekly | K13: 2 | L13: 2 | M13: =IF(OR(K13="",L13=""),"",K13*L13) -> 4 | N13: =IF(M13="","",IF(M13>=Scales!$B$21,"High",IF(M13>=Scales!$B$22,"Medium","Low"))) -> Low | O13: IT contractor | P13: 46477 | Q13: Open
A14: R-10 | B14: Guests misuse the clinic Wi-Fi | C14: PR.IR-01 | D14: 2 | E14: 2 | F14: =IF(OR(D14="",E14=""),"",D14*E14) -> 4 | G14: =IF(F14="","",IF(F14>=Scales!$B$21,"High",IF(F14>=Scales!$B$22,"Medium","Low"))) -> Low | H14: =IF(C14="","",IFERROR(INDEX('Gap Assessment'!$I$5:$I$100,MATCH(C14,'Gap Assessment'!$A$5:$A$100,0)),"Not found")) -> 1 | I14: Mitigate | J14: Separate guest Wi-Fi from the clinic network and review yearly | K14: 1 | L14: 2 | M14: =IF(OR(K14="",L14=""),"",K14*L14) -> 2 | N14: =IF(M14="","",IF(M14>=Scales!$B$21,"High",IF(M14>=Scales!$B$22,"Medium","Low"))) -> Low | O14: IT contractor | P14: 46568 | Q14: Open
F15: =IF(OR(D15="",E15=""),"",D15*E15) | G15: =IF(F15="","",IF(F15>=Scales!$B$21,"High",IF(F15>=Scales!$B$22,"Medium","Low"))) | H15: =IF(C15="","",IFERROR(INDEX('Gap Assessment'!$I$5:$I$100,MATCH(C15,'Gap Assessment'!$A$5:$A$100,0)),"Not found")) | M15: =IF(OR(K15="",L15=""),"",K15*L15) | N15: =IF(M15="","",IF(M15>=Scales!$B$21,"High",IF(M15>=Scales!$B$22,"Medium","Low")))
F16: =IF(OR(D16="",E16=""),"",D16*E16) | G16: =IF(F16="","",IF(F16>=Scales!$B$21,"High",IF(F16>=Scales!$B$22,"Medium","Low"))) | H16: =IF(C16="","",IFERROR(INDEX('Gap Assessment'!$I$5:$I$100,MATCH(C16,'Gap Assessment'!$A$5:$A$100,0)),"Not found")) | M16: =IF(OR(K16="",L16=""),"",K16*L16) | N16: =IF(M16="","",IF(M16>=Scales!$B$21,"High",IF(M16>=Scales!$B$22,"Medium","Low")))
F17: =IF(OR(D17="",E17=""),"",D17*E17) | G17: =IF(F17="","",IF(F17>=Scales!$B$21,"High",IF(F17>=Scales!$B$22,"Medium","Low"))) | H17: =IF(C17="","",IFERROR(INDEX('Gap Assessment'!$I$5:$I$100,MATCH(C17,'Gap Assessment'!$A$5:$A$100,0)),"Not found")) | M17: =IF(OR(K17="",L17=""),"",K17*L17) | N17: =IF(M17="","",IF(M17>=Scales!$B$21,"High",IF(M17>=Scales!$B$22,"Medium","Low")))
F18: =IF(OR(D18="",E18=""),"",D18*E18) | G18: =IF(F18="","",IF(F18>=Scales!$B$21,"High",IF(F18>=Scales!$B$22,"Medium","Low"))) | H18: =IF(C18="","",IFERROR(INDEX('Gap Assessment'!$I$5:$I$100,MATCH(C18,'Gap Assessment'!$A$5:$A$100,0)),"Not found")) | M18: =IF(OR(K18="",L18=""),"",K18*L18) | N18: =IF(M18="","",IF(M18>=Scales!$B$21,"High",IF(M18>=Scales!$B$22,"Medium","Low")))
F19: =IF(OR(D19="",E19=""),"",D19*E19) | G19: =IF(F19="","",IF(F19>=Scales!$B$21,"High",IF(F19>=Scales!$B$22,"Medium","Low"))) | H19: =IF(C19="","",IFERROR(INDEX('Gap Assessment'!$I$5:$I$100,MATCH(C19,'Gap Assessment'!$A$5:$A$100,0)),"Not found")) | M19: =IF(OR(K19="",L19=""),"",K19*L19) | N19: =IF(M19="","",IF(M19>=Scales!$B$21,"High",IF(M19>=Scales!$B$22,"Medium","Low")))
F20: =IF(OR(D20="",E20=""),"",D20*E20) | G20: =IF(F20="","",IF(F20>=Scales!$B$21,"High",IF(F20>=Scales!$B$22,"Medium","Low"))) | H20: =IF(C20="","",IFERROR(INDEX('Gap Assessment'!$I$5:$I$100,MATCH(C20,'Gap Assessment'!$A$5:$A$100,0)),"Not found")) | M20: =IF(OR(K20="",L20=""),"",K20*L20) | N20: =IF(M20="","",IF(M20>=Scales!$B$21,"High",IF(M20>=Scales!$B$22,"Medium","Low")))
F21: =IF(OR(D21="",E21=""),"",D21*E21) | G21: =IF(F21="","",IF(F21>=Scales!$B$21,"High",IF(F21>=Scales!$B$22,"Medium","Low"))) | H21: =IF(C21="","",IFERROR(INDEX('Gap Assessment'!$I$5:$I$100,MATCH(C21,'Gap Assessment'!$A$5:$A$100,0)),"Not found")) | M21: =IF(OR(K21="",L21=""),"",K21*L21) | N21: =IF(M21="","",IF(M21>=Scales!$B$21,"High",IF(M21>=Scales!$B$22,"Medium","Low")))
F22: =IF(OR(D22="",E22=""),"",D22*E22) | G22: =IF(F22="","",IF(F22>=Scales!$B$21,"High",IF(F22>=Scales!$B$22,"Medium","Low"))) | H22: =IF(C22="","",IFERROR(INDEX('Gap Assessment'!$I$5:$I$100,MATCH(C22,'Gap Assessment'!$A$5:$A$100,0)),"Not found")) | M22: =IF(OR(K22="",L22=""),"",K22*L22) | N22: =IF(M22="","",IF(M22>=Scales!$B$21,"High",IF(M22>=Scales!$B$22,"Medium","Low")))
F23: =IF(OR(D23="",E23=""),"",D23*E23) | G23: =IF(F23="","",IF(F23>=Scales!$B$21,"High",IF(F23>=Scales!$B$22,"Medium","Low"))) | H23: =IF(C23="","",IFERROR(INDEX('Gap Assessment'!$I$5:$I$100,MATCH(C23,'Gap Assessment'!$A$5:$A$100,0)),"Not found")) | M23: =IF(OR(K23="",L23=""),"",K23*L23) | N23: =IF(M23="","",IF(M23>=Scales!$B$21,"High",IF(M23>=Scales!$B$22,"Medium","Low")))
F24: =IF(OR(D24="",E24=""),"",D24*E24) | G24: =IF(F24="","",IF(F24>=Scales!$B$21,"High",IF(F24>=Scales!$B$22,"Medium","Low"))) | H24: =IF(C24="","",IFERROR(INDEX('Gap Assessment'!$I$5:$I$100,MATCH(C24,'Gap Assessment'!$A$5:$A$100,0)),"Not found")) | M24: =IF(OR(K24="",L24=""),"",K24*L24) | N24: =IF(M24="","",IF(M24>=Scales!$B$21,"High",IF(M24>=Scales!$B$22,"Medium","Low")))

Sheet Gap Assessment
A1: NIST CSF 2.0 Gap Assessment: 26 selected outcomes, BrightPath Dental (fictional US-based clinic)
A2: Scores use a custom 0-4 scale, not a NIST-defined scale. Gap = Target - Current. Priority score = Gap x Impact.
A4: CSF ID | B4: Function | C4: Category | D4: Requirement (short) | E4: Current state | F4: Evidence / assessment rationale (fictional) | G4: Current (0-4) | H4: Target (0-4) | I4: Gap | J4: Impact (1-5) | K4: Priority score | L4: Priority | M4: Recommended action
A5: GV.OC-03 | B5: Govern | C5: Organizational Context | D5: Legal and regulatory cyber obligations are understood and managed | E5: Owner knows HIPAA applies, but nobody tracks obligations | F5: Owner interview; no obligations list or contract review found. Scored 1: awareness without a process. | G5: 1 | H5: 3 | I5: =IF(OR(G5="",H5=""),"",MAX(0,H5-G5)) -> 2 | J5: 4 | K5: =IF(OR(I5="",J5=""),"",I5*J5) -> 8 | L5: =IF(K5="","",IF(K5>=Scales!$B$21,"High",IF(K5>=Scales!$B$22,"Medium",IF(K5>0,"Low","None")))) -> Medium | M5: Create a compliance obligations checklist (HIPAA, state breach law)
A6: GV.RM-01 | B6: Govern | C6: Risk Management Strategy | D6: Risk management objectives are set and agreed by leadership | E6: No documented risk objectives | F6: Interview and document request: no risk objectives or risk appetite statement. Scored 0. | G6: 0 | H6: 2 | I6: =IF(OR(G6="",H6=""),"",MAX(0,H6-G6)) -> 2 | J6: 3 | K6: =IF(OR(I6="",J6=""),"",I6*J6) -> 6 | L6: =IF(K6="","",IF(K6>=Scales!$B$21,"High",IF(K6>=Scales!$B$22,"Medium",IF(K6>0,"Low","None")))) -> Medium | M6: Document risk objectives with the owner
A7: GV.RR-02 | B7: Govern | C7: Roles, Responsibilities, and Authorities | D7: Cyber roles and responsibilities are defined and communicated | E7: Contractor handles everything; no named security owner | F7: Interview: contractor handles IT and security; no role descriptions. Scored 1: informal. | G7: 1 | H7: 3 | I7: =IF(OR(G7="",H7=""),"",MAX(0,H7-G7)) -> 2 | J7: 3 | K7: =IF(OR(I7="",J7=""),"",I7*J7) -> 6 | L7: =IF(K7="","",IF(K7>=Scales!$B$21,"High",IF(K7>=Scales!$B$22,"Medium",IF(K7>0,"Low","None")))) -> Medium | M7: Name an internal security lead
A8: GV.PO-01 | B8: Govern | C8: Policy | D8: Cybersecurity policy is established and enforced | E8: No written security policies | F8: Document request: no written security policies found. Scored 0. | G8: 0 | H8: 3 | I8: =IF(OR(G8="",H8=""),"",MAX(0,H8-G8)) -> 3 | J8: 4 | K8: =IF(OR(I8="",J8=""),"",I8*J8) -> 12 | L8: =IF(K8="","",IF(K8>=Scales!$B$21,"High",IF(K8>=Scales!$B$22,"Medium",IF(K8>0,"Low","None")))) -> High | M8: Write acceptable use, access control, and incident response policies
A9: GV.SC-01 | B9: Govern | C9: Supply Chain Risk Management | D9: A supply chain risk management process exists | E9: Records and billing vendors never assessed | F9: Vendor list requested: none exists; no vendor questionnaires on file. Scored 0. | G9: 0 | H9: 2 | I9: =IF(OR(G9="",H9=""),"",MAX(0,H9-G9)) -> 2 | J9: 3 | K9: =IF(OR(I9="",J9=""),"",I9*J9) -> 6 | L9: =IF(K9="","",IF(K9>=Scales!$B$21,"High",IF(K9>=Scales!$B$22,"Medium",IF(K9>0,"Low","None")))) -> Medium | M9: List vendors and send security questionnaires to critical ones
A10: ID.AM-01 | B10: Identify | C10: Asset Management | D10: Hardware inventory is maintained | E10: Laptop list is two years out of date | F10: Laptop spreadsheet reviewed: last edited two years ago. Scored 1: exists but outdated. | G10: 1 | H10: 3 | I10: =IF(OR(G10="",H10=""),"",MAX(0,H10-G10)) -> 2 | J10: 3 | K10: =IF(OR(I10="",J10=""),"",I10*J10) -> 6 | L10: =IF(K10="","",IF(K10>=Scales!$B$21,"High",IF(K10>=Scales!$B$22,"Medium",IF(K10>0,"Low","None")))) -> Medium | M10: Rebuild the hardware inventory and review it quarterly
A11: ID.AM-02 | B11: Identify | C11: Asset Management | D11: Software and services inventory is maintained | E11: Staff install their own apps; no list of cloud services | F11: Contractor interview: no software or cloud service list. Scored 1: partly known to the contractor. | G11: 1 | H11: 3 | I11: =IF(OR(G11="",H11=""),"",MAX(0,H11-G11)) -> 2 | J11: 3 | K11: =IF(OR(I11="",J11=""),"",I11*J11) -> 6 | L11: =IF(K11="","",IF(K11>=Scales!$B$21,"High",IF(K11>=Scales!$B$22,"Medium",IF(K11>0,"Low","None")))) -> Medium | M11: Inventory approved software and cloud services
A12: ID.RA-01 | B12: Identify | C12: Risk Assessment | D12: Asset vulnerabilities are identified and recorded | E12: No vulnerability scanning; patching is ad hoc | F12: Contractor interview: no scanning; patches applied by hand. Scored 0. | G12: 0 | H12: 3 | I12: =IF(OR(G12="",H12=""),"",MAX(0,H12-G12)) -> 3 | J12: 4 | K12: =IF(OR(I12="",J12=""),"",I12*J12) -> 12 | L12: =IF(K12="","",IF(K12>=Scales!$B$21,"High",IF(K12>=Scales!$B$22,"Medium",IF(K12>0,"Low","None")))) -> High | M12: Run a monthly vulnerability scan
A13: ID.RA-05 | B13: Identify | C13: Risk Assessment | D13: Risk is assessed and used to prioritize response | E13: No formal risk assessment before this register | F13: No risk assessment records found before this exercise. Scored 0. | G13: 0 | H13: 3 | I13: =IF(OR(G13="",H13=""),"",MAX(0,H13-G13)) -> 3 | J13: 4 | K13: =IF(OR(I13="",J13=""),"",I13*J13) -> 12 | L13: =IF(K13="","",IF(K13>=Scales!$B$21,"High",IF(K13>=Scales!$B$22,"Medium",IF(K13>0,"Low","None")))) -> High | M13: Keep the risk register up to date and review it quarterly
A14: PR.AA-01 | B14: Protect | C14: Identity Management, Authentication, and Access Control | D14: Identities and credentials are managed | E14: Accounts not removed promptly when staff leave | F14: Sample of 5 recent leavers: 2 accounts still active. Scored 1. | G14: 1 | H14: 3 | I14: =IF(OR(G14="",H14=""),"",MAX(0,H14-G14)) -> 2 | J14: 4 | K14: =IF(OR(I14="",J14=""),"",I14*J14) -> 8 | L14: =IF(K14="","",IF(K14>=Scales!$B$21,"High",IF(K14>=Scales!$B$22,"Medium",IF(K14>0,"Low","None")))) -> Medium | M14: Add an offboarding checklist and review accounts monthly
A15: PR.AA-03 | B15: Protect | C15: Identity Management, Authentication, and Access Control | D15: Users and devices are authenticated | E15: Shared login for patient records system; no MFA | F15: Records system settings reviewed: one shared login and MFA off. Scored 1. | G15: 1 | H15: 3 | I15: =IF(OR(G15="",H15=""),"",MAX(0,H15-G15)) -> 2 | J15: 5 | K15: =IF(OR(I15="",J15=""),"",I15*J15) -> 10 | L15: =IF(K15="","",IF(K15>=Scales!$B$21,"High",IF(K15>=Scales!$B$22,"Medium",IF(K15>0,"Low","None")))) -> Medium | M15: Create individual accounts and enable MFA
A16: PR.AA-05 | B16: Protect | C16: Identity Management, Authentication, and Access Control | D16: Access follows least privilege and is reviewed | E16: All staff can view all patient records | F16: Role listing reviewed: all staff can view all records; no access review on file. Scored 1. | G16: 1 | H16: 3 | I16: =IF(OR(G16="",H16=""),"",MAX(0,H16-G16)) -> 2 | J16: 5 | K16: =IF(OR(I16="",J16=""),"",I16*J16) -> 10 | L16: =IF(K16="","",IF(K16>=Scales!$B$21,"High",IF(K16>=Scales!$B$22,"Medium",IF(K16>0,"Low","None")))) -> Medium | M16: Define role-based access and review quarterly
... A30: RC.CO-03 | B30: Recover | C30: Incident Recovery Communication | D30: Recovery progress is communicated | E30: No plan to inform staff or patients during an outage | F30: Document request: no outage communication plan found. Scored 0. | G30: 0 | H30: 2 | I30: =IF(OR(G30="",H30=""),"",MAX(0,H30-G30)) -> 2 | J30: 3 | K30: =IF(OR(I30="",J30=""),"",I30*J30) -> 6 | L30: =IF(K30="","",IF(K30>=Scales!$B$21,"High",IF(K30>=Scales!$B$22,"Medium",IF(K30>0,"Low","None")))) -> Medium | M30: Add communication templates to the recovery plan
I31: =IF(OR(G31="",H31=""),"",MAX(0,H31-G31)) | K31: =IF(OR(I31="",J31=""),"",I31*J31) | L31: =IF(K31="","",IF(K31>=Scales!$B$21,"High",IF(K31>=Scales!$B$22,"Medium",IF(K31>0,"Low","None"))))
I32: =IF(OR(G32="",H32=""),"",MAX(0,H32-G32)) | K32: =IF(OR(I32="",J32=""),"",I32*J32) | L32: =IF(K32="","",IF(K32>=Scales!$B$21,"High",IF(K32>=Scales!$B$22,"Medium",IF(K32>0,"Low","None"))))
I33: =IF(OR(G33="",H33=""),"",MAX(0,H33-G33)) | K33: =IF(OR(I33="",J33=""),"",I33*J33) | L33: =IF(K33="","",IF(K33>=Scales!$B$21,"High",IF(K33>=Scales!$B$22,"Medium",IF(K33>0,"Low","None"))))
I34: =IF(OR(G34="",H34=""),"",MAX(0,H34-G34)) | K34: =IF(OR(I34="",J34=""),"",I34*J34) | L34: =IF(K34="","",IF(K34>=Scales!$B$21,"High",IF(K34>=Scales!$B$22,"Medium",IF(K34>0,"Low","None"))))

Sheet Gap Summary
A1: Gap Summary: Current vs Target Maturity by CSF Function
A3: Function | B3: Outcomes assessed | C3: Avg current | D3: Avg target | E3: Avg gap | F3: High priority gaps
A4: Govern | B4: =COUNTIF('Gap Assessment'!$B$5:$B$100,A4) -> 5 | C4: =IFERROR(AVERAGEIF('Gap Assessment'!$B$5:$B$100,A4,'Gap Assessment'!$G$5:$G$100),0) -> 0.4 | D4: =IFERROR(AVERAGEIF('Gap Assessment'!$B$5:$B$100,A4,'Gap Assessment'!$H$5:$H$100),0) -> 2.6 | E4: =D4-C4 -> 2.2 | F4: =COUNTIFS('Gap Assessment'!$B$5:$B$100,A4,'Gap Assessment'!$L$5:$L$100,"High") -> 1
A5: Identify | B5: =COUNTIF('Gap Assessment'!$B$5:$B$100,A5) -> 4 | C5: =IFERROR(AVERAGEIF('Gap Assessment'!$B$5:$B$100,A5,'Gap Assessment'!$G$5:$G$100),0) -> 0.5 | D5: =IFERROR(AVERAGEIF('Gap Assessment'!$B$5:$B$100,A5,'Gap Assessment'!$H$5:$H$100),0) -> 3 | E5: =D5-C5 -> 2.5 | F5: =COUNTIFS('Gap Assessment'!$B$5:$B$100,A5,'Gap Assessment'!$L$5:$L$100,"High") -> 2
A6: Protect | B6: =COUNTIF('Gap Assessment'!$B$5:$B$100,A6) -> 8 | C6: =IFERROR(AVERAGEIF('Gap Assessment'!$B$5:$B$100,A6,'Gap Assessment'!$G$5:$G$100),0) -> 1.375 | D6: =IFERROR(AVERAGEIF('Gap Assessment'!$B$5:$B$100,A6,'Gap Assessment'!$H$5:$H$100),0) -> 3 | E6: =D6-C6 -> 1.625 | F6: =COUNTIFS('Gap Assessment'!$B$5:$B$100,A6,'Gap Assessment'!$L$5:$L$100,"High") -> 0
A7: Detect | B7: =COUNTIF('Gap Assessment'!$B$5:$B$100,A7) -> 3 | C7: =IFERROR(AVERAGEIF('Gap Assessment'!$B$5:$B$100,A7,'Gap Assessment'!$G$5:$G$100),0) -> 0.66666667 | D7: =IFERROR(AVERAGEIF('Gap Assessment'!$B$5:$B$100,A7,'Gap Assessment'!$H$5:$H$100),0) -> 2.3333333 | E7: =D7-C7 -> 1.6666667 | F7: =COUNTIFS('Gap Assessment'!$B$5:$B$100,A7,'Gap Assessment'!$L$5:$L$100,"High") -> 0
A8: Respond | B8: =COUNTIF('Gap Assessment'!$B$5:$B$100,A8) -> 3 | C8: =IFERROR(AVERAGEIF('Gap Assessment'!$B$5:$B$100,A8,'Gap Assessment'!$G$5:$G$100),0) -> 0.33333333 | D8: =IFERROR(AVERAGEIF('Gap Assessment'!$B$5:$B$100,A8,'Gap Assessment'!$H$5:$H$100),0) -> 3 | E8: =D8-C8 -> 2.6666667 | F8: =COUNTIFS('Gap Assessment'!$B$5:$B$100,A8,'Gap Assessment'!$L$5:$L$100,"High") -> 2
A9: Recover | B9: =COUNTIF('Gap Assessment'!$B$5:$B$100,A9) -> 3 | C9: =IFERROR(AVERAGEIF('Gap Assessment'!$B$5:$B$100,A9,'Gap Assessment'!$G$5:$G$100),0) -> 0.33333333 | D9: =IFERROR(AVERAGEIF('Gap Assessment'!$B$5:$B$100,A9,'Gap Assessment'!$H$5:$H$100),0) -> 2.6666667 | E9: =D9-C9 -> 2.3333333 | F9: =COUNTIFS('Gap Assessment'!$B$5:$B$100,A9,'Gap Assessment'!$L$5:$L$100,"High") -> 1
A10: Overall | B10: =SUM(B4:B9) -> 26 | C10: =IFERROR(AVERAGE('Gap Assessment'!$G$5:$G$100),0) -> 0.73076923 | D10: =IFERROR(AVERAGE('Gap Assessment'!$H$5:$H$100),0) -> 2.8076923 | E10: =D10-C10 -> 2.0769231 | F10: =SUM(F4:F9) -> 6
A12: Averages cover the 26 selected outcomes. The 0-4 scale is custom, not NIST-defined.

Sheet Scales
A1: Scales, Thresholds and Summary
A3: Likelihood scale
A4: Score | B4: Level | C4: Description
A5: 1 | B5: Rare | C5: Unlikely in the next 3 years
A6: 2 | B6: Unlikely | C6: Could happen once in 1 to 3 years
A7: 3 | B7: Possible | C7: Could happen about once a year
A8: 4 | B8: Likely | C8: Expected several times a year
A9: 5 | B9: Almost certain | C9: Happening now or monthly
A11: Impact scale (used for risks and gap priority)
A12: Score | B12: Level | C12: Description
A13: 1 | B13: Negligible | C13: No data exposed, no disruption
A14: 2 | B14: Minor | C14: Small internal issue, under 1 hour of disruption
A15: 3 | B15: Moderate | C15: A few records exposed, up to 1 day of disruption
A16: 4 | B16: Major | C16: Many records exposed, 1 to 3 days of disruption, regulator notice needed
A17: 5 | B17: Severe | C17: Large breach or data loss, clinic cannot see patients, major fines
A19: Risk and gap priority thresholds
A20: Level | B20: Score at or above | C20: What to do
A21: High | B21: 12 | C21: Must be treated. Plan within 30 days.
A22: Medium | B22: 6 | C22: Treat, or accept with a written reason from the owner.
A23: Low | B23: below Medium | C23: Accept and monitor.
A24: The same cut-offs apply to risk scores, residual risk scores, and gap priority scores.
A26: Risk summary (calculates automatically)
A27: Level | B27: Inherent risks | C27: Residual risks (target)
A28: High | B28: =COUNTIF('Risk Register'!$G$5:$G$24,A28) -> 7 | C28: =COUNTIF('Risk Register'!$N$5:$N$24,A28) -> 0
A29: Medium | B29: =COUNTIF('Risk Register'!$G$5:$G$24,A29) -> 2 | C29: =COUNTIF('Risk Register'!$N$5:$N$24,A29) -> 2
A30: Low | B30: =COUNTIF('Risk Register'!$G$5:$G$24,A30) -> 1 | C30: =COUNTIF('Risk Register'!$N$5:$N$24,A30) -> 8
A31: Total | B31: =SUM(B28:B30) -> 10 | C31: =SUM(C28:C30) -> 10
A33: Maturity scale: custom 0-4 scale, not defined by NIST
A34: Score | B34: Level | C34: Description
A35: 0 | B35: Not implemented | C35: No control exists
A36: 1 | B36: Initial | C36: Informal or ad hoc
A37: 2 | B37: Partial | C37: Some controls, inconsistent
A38: 3 | B38: Defined | C38: Documented and followed
A39: 4 | B39: Managed | C39: Documented, monitored, and reviewed
A40: NIST CSF is outcome-based and does not define maturity levels. This 0-4 scale was created for this assessment.
A42: How the sheets connect
A43: 1. Assessment Info records the scope, method, assumptions, and evidence sources.
A44: 2. Gap Assessment scores 26 selected NIST CSF 2.0 outcomes for a fictional US-based clinic, with the evidence behind each score.
A45: 3. Risk Register lists the cyber risks those gaps create. The CSF ID column links each risk to its gap, and residual columns show the expected result of treatment.
A46: 4. Gap Summary charts current vs target maturity by CSF function.
...
